Workbook
Name Slicer_Category: #N/A
Name Slicer_Customer_Segment: #N/A
Name Slicer_Order_Status: #N/A
Name Slicer_Region: #N/A
Name Slicer_Years__Shipping_Date: #N/A

Sheet Dashboard

Sheet Report
E1: E-COMMERCE SALES DASHBOARD REPORT
D3: 1. Sales Performance
D4: The business generated total sales of ₹10.79Cr from 963 orders and sold 3,420 units during the selected periods.
D5: 2.Category Sales
D6: Electronics Contributed the Highest Share of total sales among all Category.
D7: 3.Sales Channel
D8: Online Sales Channel Generated The Majority Of Sales Revenue.
D9: 4.Region Comparison
D10: South Region recorded the highest sales while Central Region Generated the Lowest Sales.
D11: 5.Top 5 Brands
D12: Apple,Samsung,Sony,Dell, LG Were the top revenue-generating brands.
D13: 6.Payment method
D14: Cusomer Preferred Digital Payment method over Traditional Payment methods.
... D16: July Recorded the Highest Sales,While September showed the Lowest Sales.

Sheet KPIs
A2: Total Sales | B2: Sum of Discount_Amt | C2: Original Sales | D2: Count of Order_ID | E2: Sum of Quantity
A3: 1.0362632e+08 | B3: 7731562.5 | C3: 1.0796228e+08 | D3: 1000 | E3: 3420 | G3: Total count
G4: =COUNTA(_xlfn.UNIQUE(Sales_Transactions_Raw[Order_ID])) -> 963

Sheet Month wise sales
A3: Row Labels | B3: Sum of Sales | D3: Row Labels | E3: Sum of Sales
A4: 2023 | B4: 69190780 | D4: Jan | E4: 10298993
A5: 2024 | B5: 34435541 | D5: Feb | E5: 11143709
A6: Grand Total | B6: 1.0362632e+08 | D6: Mar | E6: 11291454
D7: Apr | E7: 11107004
D8: May | E8: 9255504.2
D9: Jun | E9: 10515882
D10: Jul | E10: 6847649.2
D11: Aug | E11: 5898620
D12: Sep | E12: 7374140
D13: Oct | E13: 7807125.7
D14: Nov | E14: 5590691.1
D15: Dec | E15: 6495549.2
D16: Grand Total | E16: 1.0362632e+08

Sheet Category sales
A3: Row Labels | B3: Sum of Sales | D3: Row Labels | E3: Sum of Sales
A4: Mobile App | B4: 23551653 | D4: Appliances | E4: 18429353
A5: Online | B5: 24213525 | D5: Electronics | E5: 70886288
A6: Partner | B6: 21622199 | D6: Fashion | E6: 5458683.9
A7: Phone | B7: 19122325 | D7: Furniture | E7: 8225687.7
A8: Store | B8: 15116618 | D8: Grocery | E8: 412804.16
A9: Grand Total | B9: 1.0362632e+08 | D9: Stationery | E9: 213503.54
D10: Grand Total | E10: 1.0362632e+08

Sheet Saleschan(Sales)
A3: Row Labels | B3: Sum of Sales
A4: Mobile App | B4: 23551653
A5: Online | B5: 24213525
A6: Partner | B6: 21622199
A7: Phone | B7: 19122325
A8: Store | B8: 15116618
A9: Grand Total | B9: 1.0362632e+08

Sheet Payment method
A3: Row Labels | B3: Count of Customer_Name
A4: Cash On Delivery | B4: 122
A5: Credit Card | B5: 147
A6: Debit Card | B6: 156
A7: Emi | B7: 140
A8: Net Banking | B8: 151
A9: Upi | B9: 151
A10: Wallet | B10: 133
A11: Grand Total | B11: 1000

Sheet Regionwise
A3: Row Labels | B3: Sum of new total amt | C3: Sum of Sales | E3: Row Labels | F3: Sum of Sales
A4: Central | B4: 6887696 | C4: 6701564 | E4: Apple | F4: 15368920
A5: East | B5: 22416406 | C5: 21118018 | E5: Dell | F5: 9587010
A6: North | B6: 23429364 | C6: 22514737 | E6: Lg | F6: 6565227.1
A7: South | B7: 35153104 | C7: 33997514 | E7: Samsung | F7: 15270569
A8: West | B8: 20075707 | C8: 19294488 | E8: Sony | F8: 6634987.8
A9: Grand Total | B9: 1.0796228e+08 | C9: 1.0362632e+08 | E9: Grand Total | F9: 53426714

Sheet Sales_Transactions_Raw
A1: Order_ID | B1: Customer_Name | C1: Customer_Segment | D1: Product_Name | E1: Brand | F1: Category | G1: Sub_Category | H1: Unit_Price | I1: Sales | J1: Quantity | K1: Discount_Pct | L1: Discount_Amt | M1: Subtotal | N1: Tax_Pct | O1: Tax_Amt | P1: Shipping_Charge | Q1: new total amt | R1: Payment_Method | S1: Shipping_Method | T1: Order_Status | U1: Sales_Channel | V1: Sales_Rep | W1: Sales_Rep_Region | X1: City | Y1: State | Z1: Region | AA1: Pincode | AB1: Coupon_Code | AC1: Customer_Rating | AD1: Return_Flag | AE1: Return_Reason | AF1: Warehouse_ID | AG1: Delivery_Partner | AH1: Order Date | AI1: Shipping Date | AJ1: Delivery Date | AK1: Email | AL1: Mobile no
A2: ORD-2023006 | B2: Zubair Khan | C2: Retail | D2: Hp Laserjet 1020 | E2: Hp | F2: Electronics | G2: Printers | H2: 11670 | I2: =Sales_Transactions_Raw[[#This Row],[Unit_Price]]*Sales_Transactions_Raw[[#This Row],[Quantity]] -> 81690 | J2: 7 | K2: 5 | L2: 4084.5 | M2: 77605.5 | N2: 18 | O2: 13968.99 | P2: 0 | Q2: 91574.49 | R2: Debit Card | S2: Express | T2: Delivered | U2: Partner | V2: Suraj Verma | W2: East | X2: Udaipur | Y2: Rajasthan | Z2: North | AA2: 489202 | AB2: None | AC2: 4 | AD2: No | AE2: other | AF2: WH-12 | AG2: Delhivery | AH2: 45069 | AI2: 45075 | AJ2: 45078 | AK2: zubair_khan@gmail_com | AL2: 9654235116
A3: ORD-2023198 | B3: Archana Srivastava | C3: Retail | D3: Hp Pavilion 15 | E3: Hp | F3: Electronics | G3: Laptops | H3: 58650 | I3: =Sales_Transactions_Raw[[#This Row],[Unit_Price]]*Sales_Transactions_Raw[[#This Row],[Quantity]] -> 351900 | J3: 6 | K3: 5 | L3: 17595 | M3: 334305 | N3: 18 | O3: 60174.9 | P3: 0 | Q3: 394479.9 | R3: Emi | S3: Standard | T3: Shipped | U3: Partner | V3: Vinay Joshi | W3: Central | X3: Jodhpur | Y3: Rajasthan | Z3: North | AA3: 489581 | AB3: None | AC3: 4 | AD3: No | AE3: other | AF3: WH-03 | AG3: Dtdc | AH3: 45030 | AI3: 45034 | AJ3: 45040 | AK3: srivastava_archana@gmail_com | AL3: 7030564139
A4: ORD-2023014 | B4: Mohan Tiwari | C4: Retail | D4: Sony Bravia 55-Inch | E4: Sony | F4: Electronics | G4: Televisions | H4: 78600 | I4: =Sales_Transactions_Raw[[#This Row],[Unit_Price]]*Sales_Transactions_Raw[[#This Row],[Quantity]] -> 235800 | J4: 3 | K4: 0 | L4: 0 | M4: 235800 | N4: 18 | O4: 42444 | P4: 0 | Q4: 278244 | R4: Credit Card | S4: Standard | T4: Shipped | U4: Partner | V4: Priya Sinha | W4: West | X4: Ranchi | Y4: Jharkhand | Z4: East | AA4: 182575 | AB4: Newuser | AC4: 4 | AD4: No | AE4: other | AF4: WH-09 | AG4: Ekart | AH4: 45359 | AI4: 45364 | AJ4: 45040 | AK4: mtiwari@gmail_com | AL4: 9814893252
A5: ORD-2023124 | B5: Venkatesan Rajan | C5: Wholesale | D5: Samsung 65-Inch Qled | E5: Samsung | F5: Electronics | G5: Televisions | H5: 98240 | I5: =Sales_Transactions_Raw[[#This Row],[Unit_Price]]*Sales_Transactions_Raw[[#This Row],[Quantity]] -> 392960 | J5: 4 | K5: 5 | L5: 19648 | M5: 373312 | N5: 18 | O5: 67196.16 | P5: 0 | Q5: 440508.16 | R5: Upi | S5: Economy | T5: Shipped | U5: Partner | V5: Deepa Menon | W5: South | X5: Bengaluru | Y5: Karnataka | Z5: South | AA5: 166803 | AB5: None | AC5: 4 | AD5: No | AE5: other | AF5: WH-11 | AG5: Delhivery | AH5: 45360 | AI5: 45362 | AJ5: 45372 | AK5: venkatesan_rajan@gmail_com | AL5: 8310518347
A6: ORD-2023090 | B6: Anita Bhatt | C6: Wholesale | D6: Nikon D3500 | E6: Nikon | F6: Electronics | G6: Cameras | H6: 37090 | I6: =Sales_Transactions_Raw[[#This Row],[Unit_Price]]*Sales_Transactions_Raw[[#This Row],[Quantity]] -> 74180 | J6: 2 | K6: 0 | L6: 0 | M6: 74180 | N6: 18 | O6: 13352.4 | P6: 0 | Q6: 87532.4 | R6: Wallet | S6: Overnight | T6: Processing | U6: Online | V6: Suraj Verma | W6: East | X6: Chandigarh | Y6: Punjab | Z6: North | AA6: 162579 | AB6: Save10 | AC6: 4 | AD6: No | AE6: other | AF6: WH-09 | AG6: Amazon Logistics | AH6: 45386 | AI6: 45388 | AJ6: 45396 | AK6: anita_bhatt@outlook_com | AL6: 6602606474
A7: ORD-2023019 | B7: Paramjit Brar | C7: Retail | D7: Hp Pavilion 15 | E7: Hp | F7: Electronics | G7: Laptops | H7: 62690 | I7: =Sales_Transactions_Raw[[#This Row],[Unit_Price]]*Sales_Transactions_Raw[[#This Row],[Quantity]] -> 564210 | J7: 9 | K7: 10 | L7: 56421 | M7: 507789 | N7: 18 | O7: 91402.02 | P7: 0 | Q7: 599191.02 | R7: Credit Card | S7: Economy | T7: Delivered | U7: Partner | V7: Raj Kumar | W7: North | X7: Kanpur | Y7: Uttar Pradesh | Z7: North | AA7: 691543 | AB7: None | AC7: 4 | AD7: No | AE7: other | AF7: WH-11 | AG7: Delhivery | AH7: 44996 | AI7: 45002 | AJ7: 45007 | AK7: pbrar@gmail_com | AL7: 7079911838
A8: ORD-2023073 | B8: Mohan Tiwari | C8: Retail | D8: Lenovo Thinkpad E14 | E8: Lenovo | F8: Electronics | G8: Laptops | H8: 55250 | I8: =Sales_Transactions_Raw[[#This Row],[Unit_Price]]*Sales_Transactions_Raw[[#This Row],[Quantity]] -> 221000 | J8: 4 | K8: 10 | L8: 22100 | M8: 198900 | N8: 18 | O8: 35802 | P8: 0 | Q8: 234702 | R8: Net Banking | S8: Same Day | T8: Delivered | U8: Online | V8: Deepa Menon | W8: South | X8: Indore | Y8: Madhya Pradesh | Z8: Central | AA8: 536118 | AB8: Festive20 | AC8: 4 | AD8: No | AE8: other | AF8: WH-12 | AG8: Delhivery | AH8: 45086 | AI8: 45089 | AJ8: 45095 | AK8: mohant@gmail_com | AL8: 8680112805
A9: ORD-2023048 | B9: Vishal Chaudhary | C9: VIP | D9: Bajaj Mixer 750W | E9: Bajaj | F9: Appliances | G9: Kitchen | H9: 2940 | I9: =Sales_Transactions_Raw[[#This Row],[Unit_Price]]*Sales_Transactions_Raw[[#This Row],[Quantity]] -> 17640 | J9: 6 | K9: 0 | L9: 0 | M9: 17640 | N9: 5 | O9: 882 | P9: 0 | Q9: 18522 | R9: Credit Card | S9: Economy | T9: Processing | U9: Online | V9: Priya Sinha | W9: West | X9: Pune | Y9: Maharashtra | Z9: West | AA9: 513907 | AB9: None | AC9: 4 | AD9: No | AE9: other | AF9: WH-04 | AG9: Delhivery | AH9: 45267 | AI9: 45274 | AJ9: 45282 | AK9: vishal_chaudhary@yahoo_co_in | AL9: 9541458685
A10: ORD-2023008 | B10: Arjun Nair | C10: Wholesale | D10: Fastrack Watch | E10: Fastrack | F10: Fashion | G10: Accessories | H10: 2430 | I10: =Sales_Transactions_Raw[[#This Row],[Unit_Price]]*Sales_Transactions_Raw[[#This Row],[Quantity]] -> 9720 | J10: 4 | K10: 5 | L10: 486 | M10: 9234 | N10: 12 | O10: 1108.08 | P10: 0 | Q10: 10342.08 | R10: Emi | S10: Same Day | T10: Pending | U10: Partner | V10: Aman Bhatia | W10: West | X10: Surat | Y10: Gujarat | Z10: West | AA10: 773687 | AB10: Newuser | AC10: 4 | AD10: No | AE10: other | AF10: WH-02 | AG10: Ekart | AH10: 45128 | AI10: 45131 | AJ10: 45139 | AK10: arjun_nair@gmail_com | AL10: 6994680443
A11: ORD-2023181 | B11: Jyoti Narayan | C11: Corporate | D11: Canon Eos 200D | E11: Canon | F11: Electronics | G11: Cameras | H11: 54230 | I11: =Sales_Transactions_Raw[[#This Row],[Unit_Price]]*Sales_Transactions_Raw[[#This Row],[Quantity]] -> 162690 | J11: 3 | K11: 5 | L11: 8134.5 | M11: 154555.5 | N11: 18 | O11: 27819.99 | P11: 0 | Q11: 182375.49 | R11: Cash On Delivery | S11: Express | T11: Pending | U11: Phone | V11: Priya Sinha | W11: West | X11: Chandigarh | Y11: Punjab | Z11: North | AA11: 369250 | AB11: None | AC11: 3 | AD11: No | AE11: other | AF11: WH-05 | AG11: Ekart | AH11: 44952 | AI11: 44953 | AJ11: 44958 | AK11: jyoti_narayan@yahoo_com | AL11: 7708317278
A12: ORD-2023170 | B12: Prakash Dubey | C12: Retail | D12: Hp Laserjet 1020 | E12: Hp | F12: Electronics | G12: Printers | H12: 11660 | I12: =Sales_Transactions_Raw[[#This Row],[Unit_Price]]*Sales_Transactions_Raw[[#This Row],[Quantity]] -> 81620 | J12: 7 | K12: 0 | L12: 0 | M12: 81620 | N12: 18 | O12: 14691.6 | P12: 0 | Q12: 96311.6 | R12: Debit Card | S12: Express | T12: Delivered | U12: Online | V12: Raj Kumar | W12: North | X12: Kochi | Y12: Kerala | Z12: South | AA12: 523161 | AB12: None | AC12: 3 | AD12: No | AE12: other | AF12: WH-11 | AG12: Delhivery | AH12: 45219 | AI12: 45221 | AJ12: 45227 | AK12: dubey_prakash@rediffmail_com | AL12: 8967054668
A13: ORD-2023045 | B13: Roshni Modi | C13: Corporate | D13: Boat Rockerz 450 | E13: Boat | F13: Electronics | G13: Audio | H13: 1590 | I13: =Sales_Transactions_Raw[[#This Row],[Unit_Price]]*Sales_Transactions_Raw[[#This Row],[Quantity]] -> 3180 | J13: 2 | K13: 0 | L13: 0 | M13: 3180 | N13: 18 | O13: 572.4 | P13: 149 | Q13: 3752.4 | R13: Credit Card | S13: Economy | T13: Delivered | U13: Online | V13: Neha Kulkarni | W13: West | X13: Nashik | Y13: Maharashtra | Z13: West | AA13: 503538 | AB13: None | AC13: 4 | AD13: Yes | AE13: Late Delivery | AF13: WH-02 | AG13: Dtdc | AH13: 45315 | AI13: 45318 | AJ13: 45323 | AK13: roshni_modi@gmail_com | AL13: 6092327193
... A17: ORD-2023048 | B17: Ramachandran Pillai | C17: Retail | D17: Nilkamal Chair | E17: Nilkamal | F17: Furniture | G17: Seating | H17: 4470 | I17: =Sales_Transactions_Raw[[#This Row],[Unit_Price]]*Sales_Transactions_Raw[[#This Row],[Quantity]] -> 17880 | J17: 4 | K17: 10 | L17: 1788 | M17: 16092 | N17: 5 | O17: 804.6 | P17: 0 | Q17: 16896.6 | R17: Wallet | S17: Overnight | T17: Returned | U17: Store | V17: Neha Kulkarni | W17: West | X17: Kozhikode | Y17: Kerala | Z17: South | AA17: 392603 | AB17: None | AC17: 4 | AD17: Yes | AE17: Changed Mind | AF17: WH-08 | AG17: Dtdc | AH17: 44960 | AI17: 44962 | AJ17: 44968 | AK17: ramachandran_pillai@gmail_com | AL17: 6994717464
A18: ORD-2023087 | B18: Neha Saxena | C18: Retail | D18: Lavie Handbag | E18: Lavie | F18: Fashion | G18: Bags | H18: 2880 | I18: =Sales_Transactions_Raw[[#This Row],[Unit_Price]]*Sales_Transactions_Raw[[#This Row],[Quantity]] -> 5760 | J18: 2 | K18: 20 | L18: 1152 | M18: 4608 | N18: 12 | O18: 552.96 | P18: 0 | Q18: 5160.96 | R18: Emi | S18: Economy | T18: Delivered | U18: Mobile App | V18: Pooja Nair | W18: South | X18: Vijayawada | Y18: Andhra Pradesh | Z18: South | AB18: None | AC18: 5 | AD18: No | AE18: other | AF18: WH-07 | AG18: Delhivery | AH18: 45430 | AI18: 45431 | AJ18: 45440 | AK18: neha_saxena@gmail_com | AL18: 6876038597
A19: ORD-2023046 | B19: Roshni Modi | C19: Retail | D19: Macbook Air M2 | E19: Apple | F19: Electronics | G19: Laptops | H19: 121050 | I19: =Sales_Transactions_Raw[[#This Row],[Unit_Price]]*Sales_Transactions_Raw[[#This Row],[Quantity]] -> 121050 | J19: 1 | K19: 25 | L19: 30262.5 | M19: 90787.5 | N19: 18 | O19: 16341.75 | P19: 0 | Q19: 107129.25 | R19: Cash On Delivery | S19: Express | T19: Delivered | U19: Phone | V19: Vinay Joshi | W19: Central | X19: Jamshedpur | Y19: Jharkhand | Z19: East | AA19: 605952 | AB19: Flat500 | AC19: 5 | AD19: No | AE19: other | AF19: WH-07 | AG19: Bluedart | AH19: 45084 | AI19: 45088 | AJ19: 45094 | AK19: roshni_modi@gmail_com | AL19: 6404499727
A20: ORD-2023184 | B20: Ravi Shankar | C20: Retail | D20: Levi'S 511 Jeans | E20: Levi'S | F20: Fashion | G20: Clothing | H20: 3170 | I20: =Sales_Transactions_Raw[[#This Row],[Unit_Price]]*Sales_Transactions_Raw[[#This Row],[Quantity]] -> 19020 | J20: 6 | K20: 10 | L20: 1902 | M20: 17118 | N20: 12 | O20: 2054.16 | P20: 0 | Q20: 19172.16 | R20: Emi | S20: Express | T20: Delivered | U20: Phone | V20: Priya Sinha | W20: West | X20: Nagpur | Y20: Maharashtra | Z20: West | AA20: 503050 | AB20: None | AC20: 5 | AD20: No | AE20: other | AF20: WH-04 | AG20: Dtdc | AH20: 45441 | AI20: 45357 | AJ20: 45571 | AK20: ravi_shankar@gmail_com | AL20: 8657809134
A21: ORD-2023065 | B21: Pooja Agarwal | C21: Retail | D21: Boat Rockerz 450 | E21: Boat | F21: Electronics | G21: Audio | H21: 1430 | I21: =Sales_Transactions_Raw[[#This Row],[Unit_Price]]*Sales_Transactions_Raw[[#This Row],[Quantity]] -> 4290 | J21: 3 | K21: 10 | L21: 429 | M21: 3861 | N21: 18 | O21: 694.98 | P21: 149 | Q21: 4555.98 | R21: Credit Card | S21: Economy | T21: Delivered | U21: Mobile App | V21: Ankit Sharma | W21: North | X21: Gurugram | Y21: Haryana | Z21: North | AA21: 410097 | AB21: None | AC21: 4 | AD21: No | AE21: other | AF21: WH-04 | AG21: Dtdc | AH21: 45318 | AI21: 45323 | AJ21: 45328 | AK21: pagarwal@gmail_com | AL21: 7367136959
A22: ORD-2023182 | B22: Ajay Pandey | C22: Corporate | D22: Godrej Interio Desk | E22: Godrej | F22: Furniture | G22: Desks | H22: 17450 | I22: =Sales_Transactions_Raw[[#This Row],[Unit_Price]]*Sales_Transactions_Raw[[#This Row],[Quantity]] -> 52350 | J22: 3 | K22: 5 | L22: 2617.5 | M22: 49732.5 | N22: 5 | O22: 2486.62 | P22: 0 | Q22: 52219.12 | R22: Emi | S22: Express | T22: Shipped | U22: Online | V22: Pooja Nair | W22: South | X22: Bengaluru | Y22: Karnataka | Z22: South | AA22: 499519 | AB22: Newuser | AC22: 3 | AD22: No | AE22: other | AF22: WH-04 | AG22: Bluedart | AH22: 45067 | AI22: 45073 | AJ22: 45076 | AK22: pandey_ajay@outlook_com | AL22: 6474517123
A23: ORD-2023164 | B23: Preeti Deshpande | C23: Retail | D23: Godrej Interio Desk | E23: Godrej | F23: Furniture | G23: Desks | H23: 17740 | I23: =Sales_Transactions_Raw[[#This Row],[Unit_Price]]*Sales_Transactions_Raw[[#This Row],[Quantity]] -> 35480 | J23: 2 | K23: 0 | L23: 0 | M23: 35480 | N23: 5 | O23: 1774 | P23: 0 | Q23: 37254 | R23: Upi | S23: Economy | T23: Returned | U23: Online | V23: Pooja Nair | W23: South | X23: Jodhpur | Y23: Rajasthan | Z23: North | AA23: 586806 | AB23: Festive20 | AC23: 4 | AD23: Yes | AE23: Late Delivery | AF23: WH-11 | AG23: Dtdc | AH23: 45080 | AI23: 45263 | AJ23: 45006 | AK23: deshpande_preeti@gmail_com | AL23: 6617964053
A24: ORD-2023034 | B24: Rajeev Pawar | C24: Retail | D24: Nikon D3500 | E24: Nikon | F24: Electronics | G24: Cameras | H24: 37060 | I24: =Sales_Transactions_Raw[[#This Row],[Unit_Price]]*Sales_Transactions_Raw[[#This Row],[Quantity]] -> 37060 | J24: 1 | K24: 5 | L24: 1853 | M24: 35207 | N24: 18 | O24: 6337.26 | P24: 0 | Q24: 41544.26 | R24: Cash On Delivery | S24: Standard | T24: Delivered | U24: Mobile App | V24: Ritu Singh | W24: Central | X24: Ghaziabad | Y24: Uttar Pradesh | Z24: North | AA24: 590293 | AB24: Summer15 | AC24: 5 | AD24: No | AE24: other | AF24: WH-01 | AG24: Delhivery | AH24: 45137 | AI24: 45138 | AJ24: 45148 | AK24: rpawar@hotmail_com | AL24: 9950240268
A25: ORD-2023125 | B25: Jayesh Vora | C25: Wholesale | D25: Kurl-On King Bed | E25: Kurl-On | F25: Furniture | G25: Beds | H25: 51710 | I25: =Sales_Transactions_Raw[[#This Row],[Unit_Price]]*Sales_Transactions_Raw[[#This Row],[Quantity]] -> 51710 | J25: 1 | K25: 10 | L25: 5171 | M25: 46539 | N25: 5 | O25: 2326.95 | P25: 0 | Q25: 48865.95 | R25: Emi | S25: Same Day | T25: Shipped | U25: Phone | V25: Karim Sheikh | W25: North | X25: Noida | Y25: Uttar Pradesh | Z25: North | AA25: 693398 | AB25: None | AC25: 4 | AD25: No | AE25: other | AF25: WH-09 | AG25: Dtdc | AH25: 45381 | AI25: 45382 | AJ25: 45385 | AK25: vora_jayesh@rediffmail_com | AL25: 7673657661
A26: ORD-2023129 | B26: Varsha Shinde | C26: Retail | D26: Centuary Mattress | E26: Centuary | F26: Furniture | G26: Beds | H26: 14310 | I26: =Sales_Transactions_Raw[[#This Row],[Unit_Price]]*Sales_Transactions_Raw[[#This Row],[Quantity]] -> 42930 | J26: 3 | K26: 10 | L26: 4293 | M26: 38637 | N26: 5 | O26: 1931.85 | P26: 0 | Q26: 40568.85 | R26: Credit Card | S26: Same Day | T26: Delivered | U26: Partner | V26: Sneha Reddy | W26: South | X26: Jabalpur | Y26: Madhya Pradesh | Z26: Central | AA26: 436776 | AB26: Diwali25 | AC26: 4 | AD26: No | AE26: other | AF26: WH-10 | AG26: Dtdc | AH26: 44979 | AI26: 44982 | AJ26: 44988 | AK26: shinde_varsha@yahoo_co_in | AL26: 9094024455
A27: ORD-2023064 | B27: Sanjay Mishra | C27: Corporate | D27: Tata Tea Premium 1Kg | E27: Tata | F27: Grocery | G27: Beverages | H27: 450 | I27: =Sales_Transactions_Raw[[#This Row],[Unit_Price]]*Sales_Transactions_Raw[[#This Row],[Quantity]] -> 900 | J27: 2 | K27: 0 | L27: 0 | M27: 900 | N27: 5 | O27: 45 | P27: 49 | Q27: 945 | R27: Credit Card | S27: Same Day | T27: Delivered | U27: Partner | V27: Anjali Mehta | W27: South | X27: Gaya | Y27: Bihar | Z27: East | AA27: 781238 | AB27: None | AC27: 4 | AD27: No | AE27: other | AF27: WH-02 | AG27: Bluedart | AH27: 45010 | AI27: 45013 | AJ27: 45022 | AK27: sanjaym@gmail_com | AL27: 8451076226
A28: ORD-2023069 | B28: Hussain Ali | C28: Corporate | D28: Adidas Ultraboost 22 | E28: Adidas | F28: Fashion | G28: Footwear | H28: 14050 | I28: =Sales_Transactions_Raw[[#This Row],[Unit_Price]]*Sales_Transactions_Raw[[#This Row],[Quantity]] -> 42150 | J28: 3 | K28: 5 | L28: 2107.5 | M28: 40042.5 | N28: 12 | O28: 4805.1 | P28: 0 | Q28: 44847.6 | R28: Upi | S28: Express | T28: Delivered | U28: Mobile App | V28: Arjun Das | W28: East | X28: Vadodara | Y28: Gujarat | Z28: West | AA28: 730149 | AB28: Summer15 | AC28: 4 | AD28: No | AE28: other | AF28: WH-09 | AG28: Delhivery | AH28: 45017 | AI28: 45021 | AJ28: 45024 | AK28: hussaina@yahoo_co_in | AL28: 6432921277
A29: ORD-2023036 | B29: Kavita Reddy | C29: Retail | D29: Voltas 1.5T Ac | E29: Voltas | F29: Appliances | G29: Air Conditioners | H29: 40760 | I29: =Sales_Transactions_Raw[[#This Row],[Unit_Price]]*Sales_Transactions_Raw[[#This Row],[Quantity]] -> 122280 | J29: 3 | K29: 15 | L29: 18342 | M29: 103938 | N29: 5 | O29: 5196.9 | P29: 0 | Q29: 109134.9 | R29: Wallet | S29: Overnight | T29: Delivered | U29: Store | V29: Raj Kumar | W29: North | X29: Mangaluru | Y29: Karnataka | Z29: South | AA29: 798458 | AB29: Diwali25 | AC29: 4 | AD29: No | AE29: other | AF29: WH-10 | AG29: Amazon Logistics | AH29: 45019 | AI29: 45024 | AJ29: 45034 | AK29: kavita_reddy@gmail_com | AL29: 7037788925
A30: ORD-2023117 | B30: Jyoti Narayan | C30: Retail | D30: Pepperfry Coffee Table | E30: Pepperfry | F30: Furniture | G30: Tables | H30: 12560 | I30: =Sales_Transactions_Raw[[#This Row],[Unit_Price]]*Sales_Transactions_Raw[[#This Row],[Quantity]] -> 25120 | J30: 2 | K30: 15 | L30: 3768 | M30: 21352 | N30: 5 | O30: 1067.6 | P30: 0 | Q30: 22419.6 | R30: Wallet | S30: Overnight | T30: Shipped | U30: Online | V30: Pooja Nair | W30: South | X30: Vadodara | Y30: Gujarat | Z30: West | AA30: 750256 | AB30: None | AC30: 4 | AD30: No | AE30: other | AF30: WH-12 | AG30: Ekart | AH30: 45328 | AI30: 45330 | AJ30: 45333 | AK30: jyoti_narayan@yahoo_com | AL30: 8214188805
... A68: ORD-2023133 | B68: Rekha Menon | C68: Corporate | D68: Pepperfry Coffee Table | E68: Pepperfry | F68: Furniture | G68: Tables | H68: 11550 | I68: =Sales_Transactions_Raw[[#This Row],[Unit_Price]]*Sales_Transactions_Raw[[#This Row],[Quantity]] -> 23100 | J68: 2 | K68: 5 | L68: 1155 | M68: 21945 | N68: 5 | O68: 1097.25 | P68: 0 | Q68: 23042.25 | R68: Upi | S68: Overnight | T68: Delivered | U68: Online | V68: Sneha Reddy | W68: South | X68: Durgapur | Y68: West Bengal | Z68: East | AA68: 285285 | AB68: Summer15 | AC68: 4 | AD68: No | AE68: other | AF68: WH-04 | AG68: Delhivery | AH68: 45116 | AI68: 45119 | AJ68: 45127 | AK68: menon_rekha@yahoo_co_in | AL68: 9686879374
A69: ORD-2023241 | B69: Kruti Bhatt | C69: Retail | D69: Sony Wh-1000Xm5 | E69: Sony | F69: Electronics | G69: Audio | H69: 30240 | I69: =Sales_Transactions_Raw[[#This Row],[Unit_Price]]*Sales_Transactions_Raw[[#This Row],[Quantity]] -> 90720 | J69: 3 | K69: 20 | L69: 18144 | M69: 72576 | N69: 18 | O69: 13063.68 | P69: 0 | Q69: 85639.68 | R69: Wallet | S69: Standard | T69: Delivered | U69: Partner | V69: Priya Sinha | W69: West | X69: Ranchi | Y69: Jharkhand | Z69: East | AB69: None | AC69: 4 | AD69: No | AE69: other | AF69: WH-05 | AG69: Bluedart | AH69: 45191 | AI69: 45194 | AJ69: 45197 | AK69: kruti_bhatt@gmail_com | AL69: 61485 64679
A70: ORD-2023246 | B70: Parvati Devi | C70: Wholesale | D70: Lenovo Thinkpad E14 | E70: Lenovo | F70: Electronics | G70: Laptops | H70: 60120 | I70: =Sales_Transactions_Raw[[#This Row],[Unit_Price]]*Sales_Transactions_Raw[[#This Row],[Quantity]] -> 120240 | J70: 2 | K70: 10 | L70: 12024 | M70: 108216 | N70: 18 | O70: 19478.88 | P70: 0 | Q70: 127694.88 | R70: Net Banking | S70: Express | T70: Delivered | U70: Phone | V70: Priya Sinha | W70: West | X70: Jodhpur | Y70: Rajasthan | Z70: North | AA70: 607636 | AB70: None | AC70: 4 | AD70: No | AE70: other | AF70: WH-06 | AG70: Bluedart | AH70: 45234 | AI70: 45240 | AJ70: 45249 | AK70: devi_parvati@gmail_com | AL70: 9902330307
A71: ORD-2023135 | B71: Aarav Sharma | C71: Corporate | D71: Classmate Notebook | E71: Classmate | F71: Stationery | G71: Books | H71: 130 | I71: =Sales_Transactions_Raw[[#This Row],[Unit_Price]]*Sales_Transactions_Raw[[#This Row],[Quantity]] -> 390 | J71: 3 | K71: 20 | L71: 78 | M71: 312 | N71: 5 | O71: 15.6 | P71: 79 | Q71: 327.6 | R71: Upi | S71: Economy | T71: Shipped | U71: Partner | V71: Neha Kulkarni | W71: West | X71: Gurugram | Y71: Haryana | Z71: North | AA71: 223356 | AB71: Save10 | AC71: 5 | AD71: Yes | AE71: other | AF71: WH-05 | AG71: Dtdc | AH71: 44955 | AI71: 44959 | AJ71: 44961 | AK71: aarav_sharma@gmail_com | AL71: 7446657437
A72: ORD-2023136 | B72: Lalitha Devi | C72: Retail | D72: Parker Pen Set | E72: Parker | F72: Stationery | G72: Writing | H72: 890 | I72: =Sales_Transactions_Raw[[#This Row],[Unit_Price]]*Sales_Transactions_Raw[[#This Row],[Quantity]] -> 6230 | J72: 7 | K72: 15 | L72: 934.5 | M72: 5295.5 | N72: 5 | O72: 264.77 | P72: 0 | Q72: 5560.27 | R72: Emi | S72: Same Day | T72: Shipped | U72: Store | V72: Neha Kulkarni | W72: West | X72: Jamshedpur | Y72: Jharkhand | Z72: East | AA72: 432003 | AB72: Save10 | AC72: 4 | AD72: Yes | AE72: other | AF72: WH-06 | AG72: Delhivery | AH72: 45119 | AI72: 45121 | AJ72: 45131 | AK72: devi_lalitha@gmail_com | AL72: 738758428
A73: ORD-2023101 | B73: Kunal Oberoi | C73: Corporate | D73: Realme Gt 5 | E73: Realme | F73: Electronics | G73: Mobile Phones | H73: 27470 | I73: =Sales_Transactions_Raw[[#This Row],[Unit_Price]]*Sales_Transactions_Raw[[#This Row],[Quantity]] -> 164820 | J73: 6 | K73: 0 | L73: 0 | M73: 164820 | N73: 18 | O73: 29667.6 | P73: 0 | Q73: 194487.6 | R73: Wallet | S73: Express | T73: Delivered | U73: Store | V73: Ankit Sharma | W73: North | X73: Ranchi | Y73: Jharkhand | Z73: East | AA73: 124761 | AB73: Flat500 | AC73: 3 | AD73: Yes | AE73: other | AF73: WH-04 | AG73: Delhivery | AH73: 44999 | AI73: 45003 | AJ73: 45008 | AK73: kunalo@gmail_com | AL73: 8525007432
A74: ORD-2023064 | B74: Manoj Tomar | C74: Wholesale | D74: Classmate Notebook | E74: Classmate | F74: Stationery | G74: Books | H74: 110 | I74: =Sales_Transactions_Raw[[#This Row],[Unit_Price]]*Sales_Transactions_Raw[[#This Row],[Quantity]] -> 220 | J74: 2 | K74: 0 | L74: 0 | M74: 220 | N74: 5 | O74: 11 | P74: 99 | Q74: 231 | R74: Cash On Delivery | S74: Overnight | T74: Delivered | U74: Partner | V74: Neha Kulkarni | W74: West | X74: Madurai | Y74: Tamil Nadu | Z74: South | AA74: 231415 | AB74: Diwali25 | AC74: 3 | AD74: No | AE74: other | AF74: WH-07 | AG74: Delhivery | AH74: 45059 | AI74: 45060 | AJ74: 45068 | AK74: manojt@yahoo_com | AL74: 9033230982
A75: ORD-2023252 | B75: Ravi Shankar | C75: Wholesale | D75: Jbl Flip 6 | E75: Jbl | F75: Electronics | G75: Audio | H75: 9630 | I75: =Sales_Transactions_Raw[[#This Row],[Unit_Price]]*Sales_Transactions_Raw[[#This Row],[Quantity]] -> 38520 | J75: 4 | K75: 10 | L75: 3852 | M75: 34668 | N75: 18 | O75: 6240.24 | P75: 0 | Q75: 40908.24 | R75: Wallet | S75: Standard | T75: Delivered | U75: Partner | V75: Pooja Nair | W75: South | X75: Vadodara | Y75: Gujarat | Z75: West | AA75: 352390 | AB75: None | AC75: 4 | AD75: No | AE75: other | AF75: WH-05 | AG75: Delhivery | AH75: 44936 | AI75: 44939 | AJ75: 44947 | AK75: shankar_ravi@gmail_com | AL75: 86420 87375
A76: ORD-2023084 | B76: Archana Srivastava | C76: Retail | D76: Voltas 1.5T Ac | E76: Voltas | F76: Appliances | G76: Air Conditioners | H76: 35240 | I76: =Sales_Transactions_Raw[[#This Row],[Unit_Price]]*Sales_Transactions_Raw[[#This Row],[Quantity]] -> 176200 | J76: 5 | K76: 20 | L76: 35240 | M76: 140960 | N76: 5 | O76: 7048 | P76: 0 | Q76: 148008 | R76: Debit Card | S76: Same Day | T76: Shipped | U76: Mobile App | V76: Arjun Das | W76: East | X76: Surat | Y76: Gujarat | Z76: West | AA76: 616546 | AB76: None | AC76: 5 | AD76: No | AE76: other | AF76: WH-02 | AG76: Amazon Logistics | AH76: 45363 | AI76: 45369 | AJ76: 45372 | AK76: archana_srivastava@gmail_com | AL76: 6676212021
A77: ORD-2023242 | B77: Saurabh Kulkarni | C77: Retail | D77: Iphone 15 Pro | E77: Apple | F77: Electronics | G77: Mobile Phones | H77: 87670 | I77: =Sales_Transactions_Raw[[#This Row],[Unit_Price]]*Sales_Transactions_Raw[[#This Row],[Quantity]] -> 350680 | J77: 4 | K77: 10 | L77: 35068 | M77: 315612 | N77: 18 | O77: 56810.16 | P77: 0 | Q77: 372422.16 | R77: Credit Card | S77: Economy | T77: Shipped | U77: Store | V77: Vinay Joshi | W77: Central | X77: Rajkot | Y77: Gujarat | Z77: West | AA77: 631534 | AB77: None | AC77: 3 | AD77: No | AE77: other | AF77: WH-01 | AG77: Delhivery | AH77: 45464 | AI77: 45471 | AJ77: 45476 | AK77: saurabh_kulkarni@gmail_com | AL77: 7877217535
A78: ORD-2023218 | B78: Venkatesan Rajan | C78: Wholesale | D78: Iphone 15 Pro | E78: Apple | F78: Electronics | G78: Mobile Phones | H78: 96480 | I78: =Sales_Transactions_Raw[[#This Row],[Unit_Price]]*Sales_Transactions_Raw[[#This Row],[Quantity]] -> 385920 | J78: 4 | K78: 5 | L78: 19296 | M78: 366624 | N78: 18 | O78: 65992.32 | P78: 0 | Q78: 432616.32 | R78: Debit Card | S78: Economy | T78: Delivered | U78: Mobile App | V78: Ritu Singh | W78: Central | X78: Gurugram | Y78: Haryana | Z78: North | AA78: 727414 | AB78: None | AC78: 4 | AD78: No | AE78: other | AF78: WH-08 | AG78: Bluedart | AH78: 45238 | AI78: 45243 | AJ78: 45253 | AK78: venkatesanr@gmail_com | AL78: 6488510272
A79: ORD-2023206 | B79: Farhan Khan | C79: Corporate | D79: Levi'S 511 Jeans | E79: Levi'S | F79: Fashion | G79: Clothing | H79: 3200 | I79: =Sales_Transactions_Raw[[#This Row],[Unit_Price]]*Sales_Transactions_Raw[[#This Row],[Quantity]] -> 6400 | J79: 2 | K79: 20 | L79: 1280 | M79: 5120 | N79: 12 | O79: 614.4 | P79: 0 | Q79: 5734.4 | R79: Cash On Delivery | S79: Express | T79: Delivered | U79: Store | V79: Deepa Menon | W79: South | X79: Mumbai | Y79: Maharashtra | Z79: West | AA79: 638371 | AB79: Festive20 | AC79: 3 | AD79: No | AE79: other | AF79: WH-11 | AG79: Bluedart | AH79: 44976 | AI79: 44981 | AJ79: 44989 | AK79: farhank@gmail_com | AL79: 7472269848
A80: ORD-2023168 | B80: Meenakshi Sundaram | C80: Corporate | D80: Puma Softride | E80: Puma | F80: Fashion | G80: Footwear | H80: 5250 | I80: =Sales_Transactions_Raw[[#This Row],[Unit_Price]]*Sales_Transactions_Raw[[#This Row],[Quantity]] -> 31500 | J80: 6 | K80: 10 | L80: 3150 | M80: 28350 | N80: 12 | O80: 3402 | P80: 0 | Q80: 31752 | R80: Debit Card | S80: Standard | T80: Delivered | U80: Online | V80: Ankit Sharma | W80: North | X80: Cuttack | Y80: Odisha | Z80: East | AA80: 373551 | AB80: Flat500 | AC80: 1 | AD80: No | AE80: other | AF80: WH-08 | AG80: Ekart | AH80: 45354 | AI80: 45360 | AJ80: 45370 | AK80: msundaram@gmail_com | AL80: 8057198386
...

Sheet Sheet2
F3: =Sales_Transactions_Raw!H2*Sales_Transactions_Raw!J2 -> 81690 | H3: =Sales_Transactions_Raw!M2*Sales_Transactions_Raw!N2 -> 1396899
F4: =F3*5% -> 4084.5 | I4: =H3+Sales_Transactions_Raw!M2 -> 1474504.5
F5: =F3-F4 -> 77605.5
G7: =(Sales_Transactions_Raw!H2*Sales_Transactions_Raw!J2)-Sales_Transactions_Raw!K2 -> 81685

Sheet Sheet1
B2: ETL | C2: extract | D2: raw data(we can get data from different sources)
C3: transform | D3: data cleaning | E3: power query
C4: load | D4: ready to analize,ready visualize
H5: =Sales_Transactions_Raw!H2*Sales_Transactions_Raw!J2*Sales_Transactions_Raw!K2 -> 408450
H11: saurabh.kulkarni@@gmail.com
